Traceback (most recent call last):
  File "/opt/hostedtoolcache/Python/3.7.17/x64/lib/python3.7/site-packages/nbclient/client.py", line 730, in _async_poll_for_reply
    msg = await ensure_async(self.kc.shell_channel.get_msg(timeout=new_timeout))
  File "/opt/hostedtoolcache/Python/3.7.17/x64/lib/python3.7/site-packages/nbclient/util.py", line 96, in ensure_async
    result = await obj
  File "/opt/hostedtoolcache/Python/3.7.17/x64/lib/python3.7/site-packages/jupyter_client/channels.py", line 230, in get_msg
    raise Empty
_queue.Empty

During handling of the above exception, another exception occurred:

Traceback (most recent call last):
  File "/opt/hostedtoolcache/Python/3.7.17/x64/lib/python3.7/site-packages/jupyter_cache/executors/utils.py", line 56, in single_nb_execution
    record_timing=False,
  File "/opt/hostedtoolcache/Python/3.7.17/x64/lib/python3.7/site-packages/nbclient/client.py", line 1204, in execute
    return NotebookClient(nb=nb, resources=resources, km=km, **kwargs).execute()
  File "/opt/hostedtoolcache/Python/3.7.17/x64/lib/python3.7/site-packages/nbclient/util.py", line 84, in wrapped
    return just_run(coro(*args, **kwargs))
  File "/opt/hostedtoolcache/Python/3.7.17/x64/lib/python3.7/site-packages/nbclient/util.py", line 62, in just_run
    return loop.run_until_complete(coro)
  File "/opt/hostedtoolcache/Python/3.7.17/x64/lib/python3.7/asyncio/base_events.py", line 587, in run_until_complete
    return future.result()
  File "/opt/hostedtoolcache/Python/3.7.17/x64/lib/python3.7/site-packages/nbclient/client.py", line 664, in async_execute
    cell, index, execution_count=self.code_cells_executed + 1
  File "/opt/hostedtoolcache/Python/3.7.17/x64/lib/python3.7/site-packages/nbclient/client.py", line 949, in async_execute_cell
    exec_reply = await self.task_poll_for_reply
  File "/opt/hostedtoolcache/Python/3.7.17/x64/lib/python3.7/site-packages/nbclient/client.py", line 754, in _async_poll_for_reply
    await self._async_handle_timeout(timeout, cell)
  File "/opt/hostedtoolcache/Python/3.7.17/x64/lib/python3.7/site-packages/nbclient/client.py", line 802, in _async_handle_timeout
    "Cell execution timed out", timeout, cell
nbclient.exceptions.CellTimeoutError: A cell timed out while it was being executed, after 60 seconds.
The message was: Cell execution timed out.
Here is a preview of the cell contents:
-------------------
['# historical - wbgt_hist_raw_runmean7_gev.nc', 'fname_wbgt_hist = "wbgt_hist_raw_runmean7_gev.nc"', 'url_wbgt_hist = "https://osf.io/dakv3/download"', 'fit_sp_hist = xr.open_dataset(pooch_load(url_wbgt_hist, fname_wbgt_hist))', '']
...
['', '# SSP-585 - wbgt_585_raw_runmean7_gev_2071-2100.nc', 'fname_bgt_58 = "wbgt_585_raw_runmean7_gev_2071-2100.nc"', 'url_bgt_585 = "https://osf.io/y6edw/download"', 'fit_sp_585 = xr.open_dataset(pooch_load(url_bgt_585, fname_bgt_58))']
-------------------

